Workbook

Sheet README
B2: Insurance AI Platform — Phase 1 JIRA Export
B3: Epic / Story / Task / Subtask breakdown, generated from the real project artifacts
B5: Source of truth | C5: Every row in this workbook traces to a real artifact in github.com/btholath/insurance-ai-platform: spec.md (User Stories, FR-XXX requirements), tasks.md (all 74 tasks, including T053a/T053b added via /speckit-analyze remediation), and the /speckit-analyze coverage report (FR-to-task traceability).
B7: Hierarchy used | C7: Epic (1) → Story/Task (8, parent-level) → Subtask (74). This mirrors standard JIRA structure: 'Story' = user-facing capability (from spec.md's 5 User Stories), 'Task' = technical work with no natural user-facing framing (Setup, Foundational, Polish phases).
B9: Status as of | C9: 2026-08-01. T001-T030 (Setup + Foundational) are Done, independently verified against the live database and source code — see readme-runbook-phase1.md in the repo for the full verification trail. T031-T072 (+T053a/T053b) are To Do.
B11: How to import into real JIRA | C11: The 'Subtasks' sheet's columns (Issue Type, Summary, Parent, Description, Status, Labels) match JIRA's CSV importer field names closely enough to use directly — export that sheet as CSV, map 'Parent' to Epic Link or Parent depending on your project type (company-managed vs. team-managed), then re-run the import for the 'Stories & Tasks' sheet first so parent keys exist before subtasks reference them.
B13: Assumption disclosed | C13: JIRA issue keys (INSAI-1, INSAI-2, ...) are placeholder keys for this export — they are not real keys from a live JIRA instance, since this project has not actually been entered into JIRA. Renumber to match your real project key on import.
B15: Assumption disclosed | C15: FR-032/033/034's task mapping on the 'Traceability Matrix' sheet is marked where it was directly confirmed against a task's own cited FR number in tasks.md's text, versus where it is an inference based on requirement-text similarity — see that sheet's 'Confidence' column.

Sheet Dashboard
B2: Phase 1 Progress Dashboard
B3: All figures below are live formulas referencing the Subtasks sheet — they recalculate if task statuses change.
B5: Metric | C5: Value | D5: Notes
B6: Total subtasks | C6: =COUNTA(Subtasks!B3:B1000) -> 74 | D6: All T-numbers, including T053a/T053b
B7: Done | C7: =COUNTIF(Subtasks!E3:E1000,"Done") -> 30 | D7: T001-T030 — Setup + Foundational
B8: To Do | C8: =COUNTIF(Subtasks!E3:E1000,"To Do") -> 44 | D8: T031-T072, +T053a/T053b
B9: % Complete | C9: =C7/C6 -> 0.40540541 | D9: Done ÷ Total
B10: Parallel-capable tasks [P] | C10: =COUNTIF(Subtasks!G3:G1000,"Yes") -> 41 | D10: Can run concurrently per tasks.md
B12: Breakdown by parent Story/Task
B13: Parent Key | C13: Parent Summary | D13: Subtask Count | E13: Done | F13: To Do | G13: % Complete
B14: INSAI-2 | C14: Setup: Repository Scaffolding | D14: =COUNTIF(Subtasks!$C$3:$C$1000,B14) -> 6 | E14: =COUNTIFS(Subtasks!$C$3:$C$1000,B14,Subtasks!$E$3:$E$1000,"Done") -> 6 | F14: =COUNTIFS(Subtasks!$C$3:$C$1000,B14,Subtasks!$E$3:$E$1000,"To Do") -> 0 | G14: =IF(D14=0,0,E14/D14) -> 1
B15: INSAI-3 | C15: Foundational: Django Project, RBAC, Audit, Compose | D15: =COUNTIF(Subtasks!$C$3:$C$1000,B15) -> 24 | E15: =COUNTIFS(Subtasks!$C$3:$C$1000,B15,Subtasks!$E$3:$E$1000,"Done") -> 24 | F15: =COUNTIFS(Subtasks!$C$3:$C$1000,B15,Subtasks!$E$3:$E$1000,"To Do") -> 0 | G15: =IF(D15=0,0,E15/D15) -> 1
B16: INSAI-4 | C16: US1: Platform Runs Locally | D16: =COUNTIF(Subtasks!$C$3:$C$1000,B16) -> 5 | E16: =COUNTIFS(Subtasks!$C$3:$C$1000,B16,Subtasks!$E$3:$E$1000,"Done") -> 0 | F16: =COUNTIFS(Subtasks!$C$3:$C$1000,B16,Subtasks!$E$3:$E$1000,"To Do") -> 5 | G16: =IF(D16=0,0,E16/D16) -> 0
B17: INSAI-5 | C17: US2: Roles & RBAC Enforced | D17: =COUNTIF(Subtasks!$C$3:$C$1000,B17) -> 12 | E17: =COUNTIFS(Subtasks!$C$3:$C$1000,B17,Subtasks!$E$3:$E$1000,"Done") -> 0 | F17: =COUNTIFS(Subtasks!$C$3:$C$1000,B17,Subtasks!$E$3:$E$1000,"To Do") -> 12 | G17: =IF(D17=0,0,E17/D17) -> 0
B18: INSAI-6 | C18: US3: Unalterable Audit Record | D18: =COUNTIF(Subtasks!$C$3:$C$1000,B18) -> 12 | E18: =COUNTIFS(Subtasks!$C$3:$C$1000,B18,Subtasks!$E$3:$E$1000,"Done") -> 0 | F18: =COUNTIFS(Subtasks!$C$3:$C$1000,B18,Subtasks!$E$3:$E$1000,"To Do") -> 12 | G18: =IF(D18=0,0,E18/D18) -> 0
B19: INSAI-7 | C19: US4: System Health at a Glance | D19: =COUNTIF(Subtasks!$C$3:$C$1000,B19) -> 7 | E19: =COUNTIFS(Subtasks!$C$3:$C$1000,B19,Subtasks!$E$3:$E$1000,"Done") -> 0 | F19: =COUNTIFS(Subtasks!$C$3:$C$1000,B19,Subtasks!$E$3:$E$1000,"To Do") -> 7 | G19: =IF(D19=0,0,E19/D19) -> 0
B20: INSAI-8 | C20: US5: Automated Tests From Day One | D20: =COUNTIF(Subtasks!$C$3:$C$1000,B20) -> 4 | E20: =COUNTIFS(Subtasks!$C$3:$C$1000,B20,Subtasks!$E$3:$E$1000,"Done") -> 0 | F20: =COUNTIFS(Subtasks!$C$3:$C$1000,B20,Subtasks!$E$3:$E$1000,"To Do") -> 4 | G20: =IF(D20=0,0,E20/D20) -> 0
B21: INSAI-9 | C21: Polish & Cross-Cutting Validation | D21: =COUNTIF(Subtasks!$C$3:$C$1000,B21) -> 4 | E21: =COUNTIFS(Subtasks!$C$3:$C$1000,B21,Subtasks!$E$3:$E$1000,"Done") -> 0 | F21: =COUNTIFS(Subtasks!$C$3:$C$1000,B21,Subtasks!$E$3:$E$1000,"To Do") -> 4 | G21: =IF(D21=0,0,E21/D21) -> 0

Sheet Epic
A1: Issue Type | B1: Key | C1: Summary | D1: Description | E1: Priority | F1: Status | G1: Reporter | H1: Labels | I1: Epic Name
A2: Epic | B2: INSAI-1 | C2: Phase 1 - Foundation: Platform Skeleton & Role-Based Access | D2: This feature establishes the foundation on which every later module (Customer, Policy, Claims, Risk, Fraud, Behavior, Prompt Library, LLM Services, CRM, Dashboards, Reporting, Administration) will be built. It delivers no business-facing insurance functionality of its own. Its value is that it makes the next phases possible, and it makes the platform's two non-negotiable guarantees - server-side role enforcement and audit logging - structurally available from day one rather than retrofitted later. Scope: an identity and access foundation, a running local service environment, an operational health signal, an append-only audit record, and a working automated-test capability. (Source: spec.md Overview, specs/001-foundation-platform-skeleton/spec.md) | E2: P1 - Highest | F2: In Progress | G2: btholath | H2: phase-1, foundation, rbac, audit-logging | I2: Foundation

Sheet Stories & Tasks
A1: Issue Type | B1: Key | C1: Epic Link | D1: Summary | E1: Description | F1: Acceptance Criteria (from spec.md) | G1: Priority | H1: Status | I1: Story Points (est.) | J1: Subtask Range
A2: Task | B2: INSAI-2 | C2: INSAI-1 | D2: Setup: Repository Scaffolding & Dependency Management | E2: Repository scaffolding, dependency manifest, and Docker image definition. Nothing here is Django-app code yet. (tasks.md Phase 1: Setup) | F2: Repo has structure, dependency manifest, and container build definition before any application code is written. | G2: P2 - High | H2: Done | I2: 3 | J2: T001-T006
A3: Task | B3: INSAI-3 | C3: INSAI-1 | D3: Foundational: Django Project, User Model, RBAC, Audit, Compose | E3: Django project configuration, the custom User model (which must be in place before the first migration and cannot be swapped later), the single RBAC mechanism, the append-only audit log, Docker Compose orchestration, and the pytest/Factory Boy harness. Every user story depends on this phase. (tasks.md Phase 2: Foundational) | F3: Django project boots under Docker Compose; the custom User model and RBAC mechanism exist; the audit log is append-only at both ORM and DB layers; health check probes work; the test harness is wired. | G3: P1 - Highest | H3: Done | I3: 13 | J3: T007-T030
A4: Story | B4: INSAI-4 | C4: INSAI-1 | D4: US1: Platform Operator Runs the Whole System Locally | E4: A developer or System Administrator clones the repository onto a clean machine and brings the entire platform up locally with a single documented command sequence. The application, its database, and its cache all start and become reachable, with no external cloud service required. (spec.md User Story 1, Priority P1) | F4: Given a clean checkout, When the operator follows the documented startup sequence, Then app/db/cache all reach a running state without manual intervention beyond copying the example environment file. Data survives a restart. No service requires outbound network access. | G4: P1 - Highest | H4: To Do | I4: 3 | J4: T031-T035
A5: Story | B5: INSAI-5 | C5: INSAI-1 | D5: US2: Administrator Assigns Roles and the System Enforces Them | E5: A System Administrator creates user accounts and assigns each one exactly one of the nine organizational roles. Every restricted action is decided server-side, and refused if the role does not permit it - regardless of what the UI shows or how the request was constructed. (spec.md User Story 2, Priority P1) | F5: Given a System Administrator, When they create/patch an account's role, Then it's recorded and enforced immediately. Given any other role or an unauthenticated caller, When they attempt a restricted action, Then it is refused (403 collection / 404 detail, non-disclosing). | G5: P1 - Highest | H5: To Do | I5: 8 | J5: T036-T047
A6: Story | B6: INSAI-6 | C6: INSAI-1 | D6: US3: Compliance Officer Sees an Unalterable Record | E6: Every user-account creation and role change writes an append-only audit record with actor, action, target, timestamp, outcome, and before/after state. No part of the platform can modify or delete an existing record. (spec.md User Story 3, Priority P2) | F6: Given an admin action, When it's saved, Then an audit record is created with full required fields. Given an existing record, When modification/deletion is attempted (ORM or raw SQL), Then it is refused. A Compliance Officer can retrieve history chronologically. | G6: P2 - Medium | H6: To Do | I6: 8 | J6: T048-T057 (+T053a, T053b)
A7: Story | B7: INSAI-7 | C7: INSAI-1 | D7: US4: Operator Confirms System Health at a Glance | E7: An unauthenticated GET /health/ reports healthy/unhealthy status for Postgres and Redis within 5 seconds, identifying any failing dependency individually, without disclosing sensitive details. (spec.md User Story 4, Priority P2) | F7: Given all services up, When /health/ is queried without credentials, Then it reports healthy. Given the DB is down, When queried, Then it reports unhealthy and names the database specifically, within 5s. | G7: P2 - Medium | H7: To Do | I7: 5 | J7: T058-T064
A8: Story | B8: INSAI-8 | C8: INSAI-1 | D8: US5: Developer Writes and Runs Automated Tests From Day One | E8: A developer runs the full automated test suite with a single command, and can construct realistic test data - including users in any of the nine roles - without hand-writing setup boilerplate. (spec.md User Story 5, Priority P2) | F8: Given a fresh checkout, When the test command runs, Then the suite executes, reports pass/fail, produces coverage, and leaves dev data untouched. A test user in any role is a single factory call. | G8: P2 - Medium | H8: To Do | I8: 3 | J8: T065-T068
A9: Task | B9: INSAI-9 | C9: INSAI-1 | D9: Polish & Cross-Cutting Validation | E9: Final validation against the complete quickstart guide and constitution re-check; no new functional surface. (tasks.md Phase 8: Polish) | F9: Full quickstart.md re-run (all 5 scenarios) passes end-to-end. README/setup docs get a fresh-reader timing check against SC-001 (under 30 minutes). Final coverage report reviewed. | G9: P3 - Low | H9: To Do | I9: 3 | J9: T069-T072

Sheet Subtasks
A2: Issue Type | B2: Key | C2: Parent | D2: Summary | E2: Status | F2: Test/Impl | G2: Parallel [P] | H2: FR Reference(s)
A3: Subtask | B3: T001 | C3: INSAI-2 | D3: Create root directories per plan.md's Project Structure (config/, apps/, docker/django/, scripts/, tests/integration/) | E3: Done | F3: Implementation | G3: No
A4: Subtask | B4: T002 | C4: INSAI-2 | D4: Create pyproject.toml: Django/DRF/psycopg/redis/django-environ/gunicorn deps + pytest/factory-boy dev deps, pytest & coverage config | E4: Done | F4: Implementation | G4: No | H4: FR-031
A5: Subtask | B5: T003 | C5: INSAI-2 | D5: Create docker/django/Dockerfile (python:3.13-slim-bookworm, entrypoint scripts/entrypoint.sh) | E5: Done | F5: Implementation | G5: Yes
A6: Subtask | B6: T004 | C6: INSAI-2 | D6: Create scripts/entrypoint.sh: wait for Postgres, run migrate, exec gunicorn | E6: Done | F6: Implementation | G6: Yes
A7: Subtask | B7: T005 | C7: INSAI-2 | D7: Create .env.example listing every required setting (SECRET_KEY, DEBUG, POSTGRES_*, REDIS_URL, ALLOWED_HOSTS) | E7: Done | F7: Implementation | G7: Yes | H7: FR-004
A8: Subtask | B8: T006 | C8: INSAI-2 | D8: Create .gitignore (.env, __pycache__, .pytest_cache, htmlcov, .coverage, venv) | E8: Done | F8: Implementation | G8: Yes
A9: Subtask | B9: T007 | C9: INSAI-3 | D9: manage.py at repo root, pointing to config.settings.dev | E9: Done | F9: Implementation | G9: No
A10: Subtask | B10: T008 | C10: INSAI-3 | D10: config/__init__.py, config/wsgi.py, config/asgi.py | E10: Done | F10: Implementation | G10: No
A11: Subtask | B11: T009 | C11: INSAI-3 | D11: config/settings/base.py: INSTALLED_APPS, AUTH_USER_MODEL, django-environ, fail-fast REQUIRED_SETTINGS check | E11: Done | F11: Implementation | G11: No | H11: FR-004, FR-005
A12: Subtask | B12: T010 | C12: INSAI-3 | D12: config/settings/dev.py: imports base, local-dev overrides | E12: Done | F12: Implementation | G12: Yes
A13: Subtask | B13: T011 | C13: INSAI-3 | D13: config/settings/test.py: imports base, MD5PasswordHasher for test speed | E13: Done | F13: Implementation | G13: Yes
A14: Subtask | B14: T012 | C14: INSAI-3 | D14: config/urls.py: root URLconf mounting /health/ and each app's /api/ routes | E14: Done | F14: Implementation | G14: No
A15: Subtask | B15: T013 | C15: INSAI-3 | D15: apps/core: AppConfig + TimeStampedModel abstract base | E15: Done | F15: Implementation | G15: No
A16: Subtask | B16: T014 | C16: INSAI-3 | D16: apps/core/permissions.py: HasRole(*roles) DRF permission factory - no superuser bypass, deny-by-default, 404-not-403 on detail routes | E16: Done | F16: Implementation | G16: No | H16: FR-011, FR-012, FR-014, FR-015
A17: Subtask | B17: T015 | C17: INSAI-3 | D17: apps/accounts: __init__.py, apps.py | E17: Done | F17: Implementation | G17: Yes
A18: Subtask | B18: T016 | C18: INSAI-3 | D18: apps/accounts/models.py: Role(TextChoices) with 9 values, User(AbstractBaseUser, PermissionsMixin), user_role_valid CheckConstraint | E18: Done | F18: Implementation | G18: No | H18: FR-009, FR-010
A19: Subtask | B19: T017 | C19: INSAI-3 | D19: apps/accounts/managers.py: UserManager.create_user/create_superuser, requires role, normalizes email | E19: Done | F19: Implementation | G19: No | H19: FR-008
A20: Subtask | B20: T018 | C20: INSAI-3 | D20: Generate & commit FIRST migration for apps/accounts - must precede every other app's migration (AUTH_USER_MODEL) | E20: Done | F20: Implementation | G20: No
A21: Subtask | B21: T019 | C21: INSAI-3 | D21: apps/accounts/admin.py: register User in Django admin, exclude raw password display | E21: Done | F21: Implementation | G21: Yes
A22: Subtask | B22: T020 | C22: INSAI-3 | D22: apps/accounts/factories.py: UserFactory with per-role trait, single-call role creation | E22: Done | F22: Implementation | G22: Yes | H22: FR-030
A23: Subtask | B23: T021 | C23: INSAI-3 | D23: apps/audit: __init__.py, apps.py | E23: Done | F23: Implementation | G23: Yes
A24: Subtask | B24: T022 | C24: INSAI-3 | D24: apps/audit/models.py: AuditLog model, save()/delete() override to raise, custom queryset overriding update()/delete() | E24: Done | F24: Implementation | G24: No | H24: FR-018, FR-019, FR-023
A25: Subtask | B25: T023 | C25: INSAI-3 | D25: Generate apps/audit migration incl. RunSQL: PostgreSQL BEFORE UPDATE OR DELETE trigger audit_log_immutable | E25: Done | F25: Implementation | G25: No | H25: FR-019
A26: Subtask | B26: T024 | C26: INSAI-3 | D26: apps/audit/services.py: record_action() - writes one AuditLog row inside caller's transaction.atomic() | E26: Done | F26: Implementation | G26: Yes | H26: FR-022
A27: Subtask | B27: T025 | C27: INSAI-3 | D27: apps/audit/factories.py: AuditLogFactory for direct test construction | E27: Done | F27: Implementation | G27: Yes
A28: Subtask | B28: T026 | C28: INSAI-3 | D28: apps/health: __init__.py, apps.py | E28: Done | F28: Implementation | G28: Yes
A29: Subtask | B29: T027 | C29: INSAI-3 | D29: apps/health/checks.py: check_database()/check_cache() with 2s bounded timeouts, never raising | E29: Done | F29: Implementation | G29: No | H29: FR-027
A30: Subtask | B30: T028 | C30: INSAI-3 | D30: tests/conftest.py: shared fixtures - api_client, user_in_role, authenticated_client | E30: Done | F30: Implementation | G30: Yes
A31: Subtask | B31: T029 | C31: INSAI-3 | D31: Configure docker-compose.yml: web/db/redis services, healthchecks, named volumes, ports not published by default | E31: Done | F31: Implementation | G31: No
A32: Subtask | B32: T030 | C32: INSAI-3 | D32: Verify foundational stack boots: docker compose up --build -d, confirm healthy, migrate applies cleanly | E32: Done | F32: Implementation | G32: No | H32: FR-001
A33: Subtask | B33: T031 | C33: INSAI-4 | D33: Integration test: real DB + Redis connections succeed via configured settings | E33: To Do | F33: Test | G33: Yes
A34: Subtask | B34: T032 | C34: INSAI-4 | D34: Test: missing required env var raises ImproperlyConfigured naming the missing setting | E34: To Do | F34: Test | G34: Yes | H34: FR-005
A35: Subtask | B35: T033 | C35: INSAI-4 | D35: README.md: exact setup sequence (clone, cp .env.example .env, up --build -d, createsuperuser, verify /health/) | E35: To Do | F35: Implementation | G35: No | H35: FR-007
A36: Subtask | B36: T034 | C36: INSAI-4 | D36: Add commented-out host port mapping for db in docker-compose.yml (local psql access) | E36: To Do | F36: Implementation | G36: No
A37: Subtask | B37: T035 | C37: INSAI-4 | D37: Manually verify SC-010 (restart persistence) and SC-011 (no external network dependency) | E37: To Do | F37: Implementation | G37: No | H37: SC-010, SC-011
A38: Subtask | B38: T036 | C38: INSAI-5 | D38: Test: User rejects role outside 9 values at full_clean() and DB CheckConstraint level | E38: To Do | F38: Test | G38: Yes | H38: FR-010
A39: Subtask | B39: T037 | C39: INSAI-5 | D39: Test: HasRole matrix - unauthenticated/wrong-role/correct-role/null-role/superuser-not-bypassed | E39: To Do | F39: Test | G39: Yes | H39: FR-014
A40: Subtask | B40: T038 | C40: INSAI-5 | D40: Contract test: full 9-role x unauthenticated RBAC matrix against POST/GET /api/users/ | E40: To Do | F40: Test | G40: Yes | H40: FR-033, SC-002, SC-003
A41: Subtask | B41: T039 | C41: INSAI-5 | D41: Test: invalid role value on POST /api/users/ returns 400, no account created | E41: To Do | F41: Test | G41: Yes | H41: FR-010
...

Sheet Traceability Matrix
B2: Requirement Traceability Matrix
B3: Source: /speckit-analyze coverage report (FR-001 to FR-031, Confidence=Confirmed) and direct tasks.md text citations (FR-032 to FR-034, Confidence=Confirmed where a task explicitly cites the FR number).
B5: FR ID | C5: Requirement (from spec.md) | D5: Story | E5: Task ID(s) | F5: Confidence
B6: FR-001 | C6: Single declarative local orchestration (all services) | D6: INSAI-3 | E6: T029, T030 | F6: Confirmed (analyze report)
B7: FR-002 | C7: No required call to external cloud service | D7: INSAI-4 | E7: T035 | F7: Confirmed (analyze report)
B8: FR-003 | C8: Stored data survives stop/restart | D8: INSAI-4 | E8: T035 | F8: Confirmed (analyze report)
B9: FR-004 | C9: External config via env, example file provided | D9: INSAI-3 | E9: T005, T009 | F9: Confirmed (analyze report)
B10: FR-005 | C10: Fail-fast on missing required config | D10: INSAI-3/4 | E10: T009, T032 | F10: Confirmed (analyze report)
B11: FR-006 | C11: customers/policies/claims module layout matches BRD | D11: INSAI-5 | E11: T046 | F11: Confirmed (analyze report)
B12: FR-007 | C12: Setup/startup/test steps fully documented | D12: INSAI-4 | E12: T033 | F12: Confirmed (analyze report)
B13: FR-008 | C13: Authenticatable user accounts | D13: INSAI-3/5 | E13: T016, T017, T045 | F13: Confirmed (analyze report)
B14: FR-009 | C14: Exactly one of 9 roles per account | D14: INSAI-3 | E14: T016 | F14: Confirmed (analyze report)
B15: FR-010 | C15: Reject any role outside the 9 defined values | D15: INSAI-3/5 | E15: T016, T036, T039 | F15: Confirmed (analyze report)
B16: FR-011 | C16: Every access decision evaluated server-side | D16: INSAI-3 | E16: T014 | F16: Confirmed (analyze report)
... B39: FR-034 | C39: Tests prove audit write + immutability on account/role changes | D39: INSAI-6 | E39: T048, T049, T051 (inferred from requirement-text overlap - not explicitly FR-034-tagged in any task's own citation; verify against a live tasks.md before relying on this row) | F39: Inferred - verify
